Workbook

Sheet 1. Objective Requirement
B2: Objective: I want to analyse my own "Swiggy Behaviour"
B4: What will I analyze?
C5: 1. Most ordered item | H5: analysis categories:
C6: 2. Prefered restaurant | I6: 1. Customer level
C7: 3. Avg. Order amount | I7: 2. Order_id level
C8: 4. Delivered vs. canceled orders | I8: 3. Timely anaysis
C9: 5. Weekend vs. Weekday vs. holidays | I9: 4. Food item level
C10: 6. Order timing : | I10: 5. Restaurant level
D11: breakfast, brunch, lunch, evening snacks, dinner, post dinner
C12: 7. Food ratings by the customer
C13: 8. Offers
C14: 9. Type of food:
D15: veg, non-veg
C16: 10. Mode of payment
D17: cod, upi, debit card, credit car, netbanking, payment Wallet, corporate cards--> simple, pluxee,…
C18: 11. distance analysis
C19: 12. Cuisines:
D20: italian, north indian, south indian, chinese, thai,….
C21: 13. Rain mode.
C22: 14. refunds/returns amount
C23: 15. money saved throuhh offers
C24: 16. tip to the delivery boy
C25: …...
C33: 1. Restraurant from where I order the most? | H33: 14. Most ordered food item
C34: 2. Types of food: Veg or non-veg
C35: 3.Weekly order summary
C36: 4. Spend per week
C37: 5. When do I order the most?
D38: brk, lunch, evening snacks, dinner
C39: 6. Mode of payment:
D40: COD, UPI, Debit, Credit Card,….
C41: 7. Rating after the delivery
C42: 8. Any complaints/issue
C43: 9. Ontime vs. Delayed orders
C44: 10. Which day I order the most? Sun-sat
C45: 11. Cuisine preference
C46: 12.Coupon applied? If yes, then coupon_id---> amount
C47: 13. Do you give any tip? Total amt = tot_item + tip+ delivery + gst+ platform fee
C48: 14. high order food items
C49: 15. premium member or not
...

Sheet Swiggy_Orders_Data
A1: order_id | B1: is_coupon_applied | C1: coupon_applied | D1: offers_data | E1: order_time | F1: confirmed_time | G1: customer_id | H1: order_status | I1: delivery_boy | J1: restaurant_id | K1: restaurant_name | L1: restaurant_address | M1: restaurant_locality | N1: restaurant_city_name | O1: delivery_time_in_seconds | P1: order_total | Q1: order_total_with_tip | R1: net_total | S1: item_total | T1: free_delivery_discount_hit | U1: restaurant_order_rating | V1: restaurant_lat_lng | W1: restaurant_customer_distance | X1: coupon_code | Y1: order_payment_method | Z1: restaurant_area_name | AA1: on_time | AB1: rain_mode | AC1: Order Mod Date | AD1: area_name_code | AE1: mod restaurant name
A2: 175244332362622 | B2: TRUE | C2: SWIGGYIT | D2: [{"id":"7740ff94-cc8f-41cf-b6ec-d4c97cbd0060","super_type":"SUPERTYPE_UNSPECIFIED","total_offer_discount":120,"discount_share":{"swiggy_discount":67.2,"store_discount":52.8,"alliance_discount":0},"discount_type":"PERCENTAGE","description":"60% off","fixed_charges":{"gp":{"id":"","final_price":0}}}] | E2: 2024-05-21 12:28:52 | F2: 2024-05-21 12:29:13 | G2: 21191609 | H2: Delivered | I2: [Record] | J2: 434304 | K2: Paris Panini - Gourmet Sandwiches & Wraps | L2: No.690/A, 14th Main, 100ft Road, JP Nagar 2nd Phase, Bangalore 560078. | M2: JP Nagar | N2: Bangalore | O2: 1587 | P2: 146 | Q2: 146 | R2: 146 | S2: 225 | T2: 43 | U2: 0 | V2: 12.90649867,77.59165435 | W2: 2.2 | X2: SWIGGYIT | Y2: UPICollect | Z2: JP Nagar | AA2: FALSE | AB2: 0 | AC2: =DATEVALUE($E2) -> 45433 | AD2: JP Nagar | AE2: =IFERROR( LEFT($K2, FIND(" -", K2)-1), $K2) -> Paris Panini
A3: 175167017704058 | B3: FALSE | E3: 2024-05-20 15:00:17 | F3: 2024-05-20 15:00:38 | G3: 21191609 | H3: Delivered | I3: [Record] | J3: 12804 | K3: Nandhana Palace | L3: JP nagar, 147, 24th Main Rd, R.K Colony, Marenahalli, 2nd Phase, J. P. Nagar, Bengaluru, Karnataka 560078 | M3: JP Nagar | N3: Bangalore | O3: 1853 | P3: 555 | Q3: 555 | R3: 555 | S3: 480 | T3: 41 | U3: 0 | V3: 12.914599,77.585509 | W3: 2.2 | Y3: UPICollect | Z3: JP Nagar | AA3: FALSE | AB3: 0 | AC3: =DATEVALUE($E3) -> 45432 | AD3: JP Nagar | AE3: =IFERROR( LEFT($K3, FIND(" -", K3)-1), $K3) -> Nandhana Palace
A4: 175017114796029 | B4: TRUE | C4: MISSEDYOU | D4: [{"id":"c1399a7d-65f4-486a-ba3e-72a9d9c70cad","super_type":"SUPERTYPE_UNSPECIFIED","total_offer_discount":80,"discount_share":{"swiggy_discount":16,"store_discount":64,"alliance_discount":0},"discount_type":"PERCENTAGE","description":"40% off","fixed_charges":{"gp":{"id":"","final_price":0}}}] | E4: 2024-05-18 21:21:54 | F4: 2024-05-18 21:22:15 | G4: 21191609 | H4: Delivered | I4: [Record] | J4: 15250 | K4: The Ganache Factory - Cakes & Desserts | L4: #156, 43rd Cross, 8th Block, Next to Udupi Hub Resto, Jayanagar, Bangalore | M4: 8th Block | N4: Bangalore | O4: 1559 | P4: 382 | Q4: 382 | R4: 382 | S4: 400 | T4: 69 | U4: 0 | V4: 12.91835714,77.578127 | W4: 3.6 | X4: MISSEDYOU | Y4: UPICollect | Z4: Jayanagar | AA4: TRUE | AB4: 0 | AC4: =DATEVALUE($E4) -> 45430 | AD4: Jayanagar | AE4: =IFERROR( LEFT($K4, FIND(" -", K4)-1), $K4) -> The Ganache Factory
A5: 174973046023416 | B5: TRUE | C5: SWIGGYIT | D5: [{"id":"28bf3ebb-4a69-4a92-88a4-f491a5f86e17","super_type":"SUPERTYPE_UNSPECIFIED","total_offer_discount":39.99,"discount_share":{"swiggy_discount":0,"store_discount":39.99,"alliance_discount":0},"discount_type":"PERCENTAGE","description":"10% off","fixed_charges":{"gp":{"id":"","final_price":0}}}] | E5: 2024-05-18 09:07:26 | F5: 2024-05-18 09:07:44 | G5: 21191609 | H5: Delivered | I5: [Record] | J5: 630473 | K5: Rasayan | L5: 652,13th cross,29th main road BTM 2nd stage,560078, Bangalore Karnataka | M5: Health Bar | N5: Bangalore | O5: 3760 | P5: 421 | Q5: 421 | R5: 421 | S5: 415 | T5: 46 | U5: 0 | V5: 12.907799,77.613487 | W5: 2.5 | X5: SWIGGYIT | Y5: UPICollect | Z5: BTM 2nd Stage | AA5: FALSE | AB5: 0 | AC5: =DATEVALUE($E5) -> 45430 | AD5: BTM | AE5: =IFERROR( LEFT($K5, FIND(" -", K5)-1), $K5) -> Rasayan
A6: 174906705849277 | B6: TRUE | C6: DEALICIOUS | D6: [{"id":"91e6269d-640b-443e-a7d4-46089c0574f6","super_type":"SUPERTYPE_UNSPECIFIED","total_offer_discount":124.99,"discount_share":{"swiggy_discount":0,"store_discount":124.99,"alliance_discount":0},"discount_type":"FLAT","description":"FLAT125 off","fixed_charges":{"gp":{"id":"","final_price":0}}}] | E6: 2024-05-17 14:41:45 | F6: 2024-05-17 14:42:09 | G6: 21191609 | H6: Delivered | I6: [Record] | J6: 34363 | K6: Firangi Bake | L6: Shop No.4, Frist Floor, NGK Complex, Tavarekere Main Rd, 1st Stage, BTM Layout, Bengaluru, Karnataka 560029 ( Above DMart Ready) | M6: NGK Complex | N6: Bangalore | O6: 2257 | P6: 556 | Q6: 556 | R6: 556 | S6: 624 | T6: 35 | U6: 0 | V6: 12.920219,77.610520 | W6: 2.2 | X6: DEALICIOUS | Y6: UPICollect | Z6: BTM 1st Stage | AA6: FALSE | AB6: 0 | AC6: =DATEVALUE($E6) -> 45429 | AD6: BTM | AE6: =IFERROR( LEFT($K6, FIND(" -", K6)-1), $K6) -> Firangi Bake
A7: 174329455765789 | B7: TRUE | C7: MDM150 | D7: [{"id":"60d51c5f-a27d-407c-9d72-c55f498dea78","super_type":"SUPERTYPE_UNSPECIFIED","total_offer_discount":149.99,"discount_share":{"swiggy_discount":15,"store_discount":134.99,"alliance_discount":0},"discount_type":"FLAT","description":"Flat ₹150 off","fixed_charges":{"gp":{"id":"","final_price":0}}}] | E7: 2024-05-10 22:20:55 | F7: 2024-05-10 22:21:01 | G7: 21191609 | H7: Delivered | I7: [Record] | J7: 474244 | K7: Daily Sushi | L7: No.5, 1st Floor, 9th Main Road, 5th block, Jayanagar, 560041 | M7: 5th Block | N7: Bangalore | O7: 3262 | P7: 1062 | Q7: 1062 | R7: 1062 | S7: 1050 | T7: 45 | U7: 0 | V7: 12.92243257,77.58390586 | W7: 3.2 | X7: MDM150 | Y7: Cash | Z7: Jayanagar | AA7: FALSE | AB7: 0 | AC7: =DATEVALUE($E7) -> 45422 | AD7: Jayanagar | AE7: =IFERROR( LEFT($K7, FIND(" -", K7)-1), $K7) -> Daily Sushi
A8: 174318296922309 | B8: TRUE | C8: SWIGGYIT | D8: [{"id":"7740ff94-cc8f-41cf-b6ec-d4c97cbd0060","super_type":"SUPERTYPE_UNSPECIFIED","total_offer_discount":120,"discount_share":{"swiggy_discount":67.2,"store_discount":52.8,"alliance_discount":0},"discount_type":"PERCENTAGE","description":"60% off","fixed_charges":{"gp":{"id":"","final_price":0}}}] | E8: 2024-05-10 19:14:56 | F8: 2024-05-10 19:15:01 | G8: 21191609 | H8: Delivered | I8: [Record] | J8: 434304 | K8: Paris Panini - Gourmet Sandwiches & Wraps | L8: No.690/A, 14th Main, 100ft Road, JP Nagar 2nd Phase, Bangalore 560078. | M8: JP Nagar | N8: Bangalore | O8: 2401 | P8: 440 | Q8: 440 | R8: 440 | S8: 480 | T8: 45 | U8: 0 | V8: 12.90649867,77.59165435 | W8: 2.1 | X8: SWIGGYIT | Y8: Cash | Z8: JP Nagar | AA8: FALSE | AB8: 0 | AC8: =DATEVALUE($E8) -> 45422 | AD8: JP Nagar | AE8: =IFERROR( LEFT($K8, FIND(" -", K8)-1), $K8) -> Paris Panini
A9: 174118005152904 | B9: TRUE | C9: SWIGGYIT | D9: [{"id":"8a02a1ac-9efe-46ea-9649-fc635c7c8618","super_type":"SUPERTYPE_UNSPECIFIED","total_offer_discount":35,"discount_share":{"swiggy_discount":0,"store_discount":35,"alliance_discount":0},"discount_type":"PERCENTAGE","description":"10% off","fixed_charges":{"gp":{"id":"","final_price":0}}}] | E9: 2024-05-08 11:36:45 | F9: 2024-05-08 11:37:28 | G9: 21191609 | H9: Delivered | I9: [Record] | J9: 534276 | K9: Naalnaad Mane | L9: 16,2ND FLOOR GOWRY'S BUILDING,ABOVE DOMINO'S,SY NO 13 OF AREKERE VILLAGE,BANNERGHATTA,BANGLAORE,jayanagar,B.B.M.PM south, karnataka - 560076 | M9: Mico Layout | N9: Bangalore | O9: 2824 | P9: 352 | Q9: 352 | R9: 352 | S9: 350 | T9: 36 | U9: 0 | V9: 12.89009167,77.5976944 | W9: 3.2 | X9: SWIGGYIT | Y9: UPICollect | Z9: Arekere | AA9: TRUE | AB9: 0 | AC9: =DATEVALUE($E9) -> 45420 | AD9: Arekere | AE9: =IFERROR( LEFT($K9, FIND(" -", K9)-1), $K9) -> Naalnaad Mane
A10: 174075356745024 | B10: FALSE | E10: 2024-05-07 23:45:56 | F10: 2024-05-07 23:46:17 | G10: 21191609 | H10: Delivered | I10: [Record] | J10: 524936 | K10: Theobroma | L10: SHOP NO-39,SHABARI ARCADE,14TH MAIN ROAD,OPP MAX SHOWROOM, HSR LAYOUT,BANGALORE-560102, BTM Layout , B.B.M.P South, Karnataka-560102 | M10: 7th Sector | N10: Bangalore | O10: 2011 | P10: 644 | Q10: 644 | R10: 644 | S10: 275 | T10: 71 | U10: 0 | V10: 12.91135428,77.6380469 | W10: 5.2 | Y10: UPICollect | Z10: HSR Layout | AA10: TRUE | AB10: 0 | AC10: =DATEVALUE($E10) -> 45419 | AD10: HSR | AE10: =IFERROR( LEFT($K10, FIND(" -", K10)-1), $K10) -> Theobroma
A11: 174067299373268 | B11: FALSE | E11: 2024-05-07 21:31:39 | F11: 2024-05-07 21:31:57 | G11: 21191609 | H11: Delivered | I11: [Record] | J11: 437065 | K11: Theobroma | L11: SHOP NO. 475, GROUND FLOOR, 39TH "C" CROSS, 9TH MAIN, 5THBLOCK, JAYANAGAR,BANGALORE, Jayanagar ,B.B.M.P South, Karnataka,560041 | M11: 5th block | N11: Bangalore | O11: 1455 | P11: 387 | Q11: 387 | R11: 387 | S11: 275 | T11: 0 | U11: 0 | V11: 12.92017647,77.5836421 | W11: 3.2 | Y11: UPICollect | Z11: Jayanagar | AA11: TRUE | AB11: 0 | AC11: =DATEVALUE($E11) -> 45419 | AD11: Jayanagar | AE11: =IFERROR( LEFT($K11, FIND(" -", K11)-1), $K11) -> Theobroma
A12: 174058332503576 | B12: TRUE | C12: SWIGGYIT | D12: [{"id":"8a02a1ac-9efe-46ea-9649-fc635c7c8618","super_type":"SUPERTYPE_UNSPECIFIED","total_offer_discount":28,"discount_share":{"swiggy_discount":0,"store_discount":28,"alliance_discount":0},"discount_type":"PERCENTAGE","description":"10% off","fixed_charges":{"gp":{"id":"","final_price":0}}}] | E12: 2024-05-07 19:02:12 | F12: 2024-05-07 19:02:53 | G12: 21191609 | H12: Delivered | I12: [Record] | J12: 534276 | K12: Naalnaad Mane | L12: 16,2ND FLOOR GOWRY'S BUILDING,ABOVE DOMINO'S,SY NO 13 OF AREKERE VILLAGE,BANNERGHATTA,BANGLAORE,jayanagar,B.B.M.PM south, karnataka - 560076 | M12: Mico Layout | N12: Bangalore | O12: 4292 | P12: 320 | Q12: 320 | R12: 320 | S12: 280 | T12: 0 | U12: 0 | V12: 12.89009167,77.5976944 | W12: 3.2 | X12: SWIGGYIT | Y12: UPICollect | Z12: Arekere | AA12: FALSE | AB12: 0 | AC12: =DATEVALUE($E12) -> 45419 | AD12: Arekere | AE12: =IFERROR( LEFT($K12, FIND(" -", K12)-1), $K12) -> Naalnaad Mane
A13: 174037702433562 | B13: TRUE | C13: TRYNEW | D13: [{"id":"5c8d9a7d-f899-4dcc-998e-d3e0b2960661","super_type":"SUPERTYPE_UNSPECIFIED","total_offer_discount":80,"discount_share":{"swiggy_discount":0,"store_discount":80,"alliance_discount":0},"discount_type":"PERCENTAGE","description":"40% off","fixed_charges":{"gp":{"id":"","final_price":0}}}] | E13: 2024-05-07 13:18:22 | F13: 2024-05-07 13:18:44 | G13: 21191609 | H13: Delivered | I13: [Record] | J13: 34363 | K13: Firangi Bake | L13: Shop No.4, Frist Floor, NGK Complex, Tavarekere Main Rd, 1st Stage, BTM Layout, Bengaluru, Karnataka 560029 ( Above DMart Ready) | M13: NGK Complex | N13: Bangalore | O13: 2730 | P13: 320 | Q13: 320 | R13: 320 | S13: 325 | T13: 0 | U13: 0 | V13: 12.920219,77.610520 | W13: 2.2 | X13: TRYNEW | Y13: UPICollect | Z13: BTM 1st Stage | AA13: FALSE | AB13: 0 | AC13: =DATEVALUE($E13) -> 45419 | AD13: BTM | AE13: =IFERROR( LEFT($K13, FIND(" -", K13)-1), $K13) -> Firangi Bake
A14: 174026206595017 | B14: TRUE | C14: SWIGGYIT | D14: [{"id":"28bf3ebb-4a69-4a92-88a4-f491a5f86e17","super_type":"SUPERTYPE_UNSPECIFIED","total_offer_discount":23.9,"discount_share":{"swiggy_discount":0,"store_discount":23.9,"alliance_discount":0},"discount_type":"PERCENTAGE","description":"10% off","fixed_charges":{"gp":{"id":"","final_price":0}}}] | E14: 2024-05-07 10:06:46 | F14: 2024-05-07 10:07:00 | G14: 21191609 | H14: Delivered | I14: [Record] | J14: 630473 | K14: Rasayan | L14: 652,13th cross,29th main road BTM 2nd stage,560078, Bangalore Karnataka | M14: Health Bar | N14: Bangalore | O14: 1927 | P14: 275 | Q14: 275 | R14: 275 | S14: 239 | T14: 10 | U14: 0 | V14: 12.907799,77.613487 | W14: 2.5 | X14: SWIGGYIT | Y14: UPICollect | Z14: BTM 2nd Stage | AA14: TRUE | AB14: 0 | AC14: =DATEVALUE($E14) -> 45419 | AD14: BTM | AE14: =IFERROR( LEFT($K14, FIND(" -", K14)-1), $K14) -> Rasayan
A15: 173972919485563 | B15: TRUE | C15: SWIGGYIT | D15: [{"id":"137a1aed-678a-41ce-ac11-088fcce35f29","super_type":"SUPERTYPE_UNSPECIFIED","total_offer_discount":100,"discount_share":{"swiggy_discount":48,"store_discount":52,"alliance_discount":0},"discount_type":"PERCENTAGE","description":"50% off","fixed_charges":{"gp":{"id":"","final_price":0}}}] | E15: 2024-05-06 19:18:39 | F15: 2024-05-06 19:19:03 | G15: 21191609 | H15: Delivered | I15: [Record] | J15: 434304 | K15: Paris Panini - Gourmet Sandwiches & Wraps | L15: No.690/A, 14th Main, 100ft Road, JP Nagar 2nd Phase, Bangalore 560078. | M15: JP Nagar | N15: Bangalore | O15: 2041 | P15: 334 | Q15: 334 | R15: 334 | S15: 385 | T15: 42 | U15: 0 | V15: 12.90649867,77.59165435 | W15: 2.1 | X15: SWIGGYIT | Y15: UPICollect | Z15: JP Nagar | AA15: FALSE | AB15: 0 | AC15: =DATEVALUE($E15) -> 45418 | AD15: JP Nagar | AE15: =IFERROR( LEFT($K15, FIND(" -", K15)-1), $K15) -> Paris Panini
A16: 173961191807457 | B16: FALSE | E16: 2024-05-06 16:03:12 | F16: 2024-05-06 16:03:45 | G16: 21191609 | H16: Delivered | I16: [Record] | J16: 694704 | K16: Love And Crumble | L16: NO 307, LALEHZAR APARTMENTS PALACE ROAD SHIVAJINAGARA B.B.M.P EAST KARNATAKA | M16: Lalehzar Apartments Palace Road | N16: Bangalore | O16: 4528 | P16: 509 | Q16: 509 | R16: 509 | S16: 370 | T16: 0 | U16: 0 | V16: 12.98505012,77.5880017 | W16: 10.2 | Y16: UPICollect | Z16: Malleshwaram | AA16: TRUE | AB16: 0 | AC16: =DATEVALUE($E16) -> 45418 | AD16: Malleshwaram | AE16: =IFERROR( LEFT($K16, FIND(" -", K16)-1), $K16) -> Love And Crumble
A17: 173953404362535 | B17: TRUE | C17: DEALICIOUS | D17: [{"id":"8ecc3140-454d-483f-810e-78be04d68af5","super_type":"SUPERTYPE_UNSPECIFIED","total_offer_discount":124.99,"discount_share":{"swiggy_discount":0,"store_discount":124.99,"alliance_discount":0},"discount_type":"FLAT","description":"FLAT125 off","fixed_charges":{"gp":{"id":"","final_price":0}}}] | E17: 2024-05-06 13:53:24 | F17: 2024-05-06 13:53:46 | G17: 21191609 | H17: Delivered | I17: [Record] | J17: 34381 | K17: Firangi Bake | L17: No 87/15/638/2 Nanjappa garden, Katha no - 1785/87/15/638/2, Arekere Village, begur hobali, Bangalore South taluk, Bangalore - 560076 | M17: Begur Hobali | N17: Bangalore | O17: 3728 | P17: 556 | Q17: 556 | R17: 556 | S17: 624 | T17: 48 | U17: 0 | V17: 12.885643,77.602120 | W17: 3.4 | X17: DEALICIOUS | Y17: UPICollect | Z17: Arekere | AA17: FALSE | AB17: 0 | AC17: =DATEVALUE($E17) -> 45418 | AD17: Arekere | AE17: =IFERROR( LEFT($K17, FIND(" -", K17)-1), $K17) -> Firangi Bake
A18: 173934793528823 | B18: TRUE | C18: SWIGGYIT | D18: [{"id":"28bf3ebb-4a69-4a92-88a4-f491a5f86e17","super_type":"SUPERTYPE_UNSPECIFIED","total_offer_discount":23.9,"discount_share":{"swiggy_discount":0,"store_discount":23.9,"alliance_discount":0},"discount_type":"PERCENTAGE","description":"10% off","fixed_charges":{"gp":{"id":"","final_price":0}}}] | E18: 2024-05-06 08:43:13 | F18: 2024-05-06 08:43:38 | G18: 21191609 | H18: Delivered | I18: [Record] | J18: 630473 | K18: Rasayan | L18: 652,13th cross,29th main road BTM 2nd stage,560078, Bangalore Karnataka | M18: Health Bar | N18: Bangalore | O18: 2470 | P18: 242 | Q18: 242 | R18: 242 | S18: 239 | T18: 43 | U18: 0 | V18: 12.907799,77.613487 | W18: 2.5 | X18: SWIGGYIT | Y18: UPICollect | Z18: BTM 2nd Stage | AA18: FALSE | AB18: 0 | AC18: =DATEVALUE($E18) -> 45418 | AD18: BTM | AE18: =IFERROR( LEFT($K18, FIND(" -", K18)-1), $K18) -> Rasayan
A19: 173886476249693 | B19: TRUE | C19: SWIGGYIT | D19: [{"id":"28bf3ebb-4a69-4a92-88a4-f491a5f86e17","super_type":"SUPERTYPE_UNSPECIFIED","total_offer_discount":40,"discount_share":{"swiggy_discount":0,"store_discount":40,"alliance_discount":0},"discount_type":"PERCENTAGE","description":"10% off","fixed_charges":{"gp":{"id":"","final_price":0}}}] | E19: 2024-05-05 19:17:56 | F19: 2024-05-05 19:18:22 | G19: 21191609 | H19: Delivered | I19: [Record] | J19: 630473 | K19: Rasayan | L19: 652,13th cross,29th main road BTM 2nd stage,560078, Bangalore Karnataka | M19: Health Bar | N19: Bangalore | O19: 1594 | P19: 487 | Q19: 487 | R19: 487 | S19: 478 | T19: 36 | U19: 0 | V19: 12.907799,77.613487 | W19: 2.5 | X19: SWIGGYIT | Y19: UPICollect | Z19: BTM 2nd Stage | AA19: TRUE | AB19: 0 | AC19: =DATEVALUE($E19) -> 45417 | AD19: BTM | AE19: =IFERROR( LEFT($K19, FIND(" -", K19)-1), $K19) -> Rasayan
A20: 173848012476255 | B20: TRUE | C20: JUMBO | D20: [{"id":"7b5f26f9-18b8-4c51-aed1-b1e142eba2ae","super_type":"SUPERTYPE_UNSPECIFIED","total_offer_discount":149.4,"discount_share":{"swiggy_discount":0,"store_discount":149.4,"alliance_discount":0},"discount_type":"PERCENTAGE","description":"30% off","fixed_charges":{"gp":{"id":"","final_price":0}}}] | E20: 2024-05-05 08:36:52 | F20: 2024-05-05 08:37:10 | G20: 21191609 | H20: Delivered | I20: [Record] | J20: 630473 | K20: Rasayan | L20: 652,13th cross,29th main road BTM 2nd stage,560078, Bangalore Karnataka | M20: Health Bar | N20: Bangalore | O20: 2999 | P20: 392 | Q20: 392 | R20: 392 | S20: 498 | T20: 43 | U20: 0 | V20: 12.907799,77.613487 | W20: 2.5 | X20: JUMBO | Y20: UPICollect | Z20: BTM 2nd Stage | AA20: FALSE | AB20: 0 | AC20: =DATEVALUE($E20) -> 45417 | AD20: BTM | AE20: =IFERROR( LEFT($K20, FIND(" -", K20)-1), $K20) -> Rasayan
A21: 173787961265182 | B21: TRUE | C21: TRYNEW | D21: [{"id":"903b3cd1-104b-4bdd-94d3-96daaea1a80b","super_type":"SUPERTYPE_UNSPECIFIED","total_offer_discount":44.99,"discount_share":{"swiggy_discount":0,"store_discount":44.99,"alliance_discount":0},"discount_type":"PERCENTAGE","description":"15% off","fixed_charges":{"gp":{"id":"","final_price":0}}}] | E21: 2024-05-04 15:56:01 | F21: 2024-05-04 15:56:19 | G21: 21191609 | H21: Delivered | I21: [Record] | J21: 534276 | K21: Naalnaad Mane | L21: 16,2ND FLOOR GOWRY'S BUILDING,ABOVE DOMINO'S,SY NO 13 OF AREKERE VILLAGE,BANNERGHATTA,BANGLAORE,jayanagar,B.B.M.PM south, karnataka - 560076 | M21: Mico Layout | N21: Bangalore | O21: 2684 | P21: 680 | Q21: 680 | R21: 680 | S21: 660 | T21: 33 | U21: 0 | V21: 12.89009167,77.5976944 | W21: 2.7 | X21: TRYNEW | Y21: UPICollect | Z21: Arekere | AA21: TRUE | AB21: 0 | AC21: =DATEVALUE($E21) -> 45416 | AD21: Arekere | AE21: =IFERROR( LEFT($K21, FIND(" -", K21)-1), $K21) -> Naalnaad Mane
A22: 173627120783219 | B22: TRUE | C22: MISSEDYOU | D22: [{"id":"bcdcaa8c-6d73-46c7-af56-3b6dc93e207a","super_type":"SUPERTYPE_UNSPECIFIED","total_offer_discount":60,"discount_share":{"swiggy_discount":12,"store_discount":48,"alliance_discount":0},"discount_type":"PERCENTAGE","description":"30% off","fixed_charges":{"gp":{"id":"","final_price":0}}}] | E22: 2024-05-02 19:15:20 | F22: 2024-05-02 19:15:26 | G22: 21191609 | H22: Delivered | I22: [Record] | J22: 35953 | K22: Homely | L22: No. 135/14, 100ft Ring Road, 15th Cross, J.P.Nagar, 3rd Phase, Bengaluru.560076 | M22: 3rd Phase | N22: Bangalore | O22: 1654 | P22: 214 | Q22: 214 | R22: 214 | S22: 239 | T22: 54 | U22: 0 | V22: 12.906291,77.596256 | W22: 1.6 | X22: MISSEDYOU | Y22: Cash | Z22: JP Nagar | AA22: TRUE | AB22: 2 | AC22: =DATEVALUE($E22) -> 45414 | AD22: JP Nagar | AE22: =IFERROR( LEFT($K22, FIND(" -", K22)-1), $K22) -> Homely
A23: 173528899495632 | B23: TRUE | C23: TRYNEW | D23: [{"id":"6efa58fe-50e0-4c94-aadd-f2cf8ce25c67","super_type":"SUPERTYPE_UNSPECIFIED","total_offer_discount":99.99000000000001,"discount_share":{"swiggy_discount":47.99,"store_discount":52,"alliance_discount":0},"discount_type":"PERCENTAGE","description":"50% off","fixed_charges":{"gp":{"id":"","final_price":0}}}] | E23: 2024-05-01 15:58:19 | F23: 2024-05-01 15:58:57 | G23: 21191609 | H23: Delivered | I23: [Record] | J23: 434304 | K23: Paris Panini - Gourmet Sandwiches & Wraps | L23: No.690/A, 14th Main, 100ft Road, JP Nagar 2nd Phase, Bangalore 560078. | M23: JP Nagar | N23: Bangalore | O23: 2161 | P23: 696 | Q23: 696 | R23: 696 | S23: 680 | T23: 36 | U23: 0 | V23: 12.90649867,77.59165435 | W23: 2.1 | X23: TRYNEW | Y23: UPICollect | Z23: JP Nagar | AA23: FALSE | AB23: 0 | AC23: =DATEVALUE($E23) -> 45413 | AD23: JP Nagar | AE23: =IFERROR( LEFT($K23, FIND(" -", K23)-1), $K23) -> Paris Panini
A24: 173508364352211 | B24: TRUE | C24: JUMBO | D24: [{"id":"7b5f26f9-18b8-4c51-aed1-b1e142eba2ae","super_type":"SUPERTYPE_UNSPECIFIED","total_offer_discount":148.8,"discount_share":{"swiggy_discount":0,"store_discount":148.8,"alliance_discount":0},"discount_type":"PERCENTAGE","description":"30% off","fixed_charges":{"gp":{"id":"","final_price":0}}}] | E24: 2024-05-01 10:16:04 | F24: 2024-05-01 10:16:24 | G24: 21191609 | H24: Delivered | I24: [Record] | J24: 630473 | K24: Rasayan | L24: 652,13th cross,29th main road BTM 2nd stage,560078, Bangalore Karnataka | M24: Health Bar | N24: Bangalore | O24: 2775 | P24: 399 | Q24: 399 | R24: 399 | S24: 496 | T24: 43 | U24: 0 | V24: 12.907799,77.613487 | W24: 2.5 | X24: JUMBO | Y24: UPICollect | Z24: BTM 2nd Stage | AA24: FALSE | AB24: 0 | AC24: =DATEVALUE($E24) -> 45413 | AD24: BTM | AE24: =IFERROR( LEFT($K24, FIND(" -", K24)-1), $K24) -> Rasayan
A25: 173162395766364 | B25: TRUE | C25: JUMBO | D25: [{"id":"7b5f26f9-18b8-4c51-aed1-b1e142eba2ae","super_type":"SUPERTYPE_UNSPECIFIED","total_offer_discount":149.99,"discount_share":{"swiggy_discount":0,"store_discount":149.99,"alliance_discount":0},"discount_type":"PERCENTAGE","description":"30% off","fixed_charges":{"gp":{"id":"","final_price":0}}}] | E25: 2024-04-27 10:09:55 | F25: 2024-04-27 10:10:09 | G25: 21191609 | H25: Delivered | I25: [Record] | J25: 630473 | K25: Rasayan | L25: 652,13th cross,29th main road BTM 2nd stage,560078, Bangalore Karnataka | M25: Health Bar | N25: Bangalore | O25: 2197 | P25: 489 | Q25: 489 | R25: 489 | S25: 580 | T25: 43 | U25: 0 | V25: 12.907799,77.613487 | W25: 2.5 | X25: JUMBO | Y25: UPICollect | Z25: BTM 2nd Stage | AA25: FALSE | AB25: 0 | AC25: =DATEVALUE($E25) -> 45409 | AD25: BTM | AE25: =IFERROR( LEFT($K25, FIND(" -", K25)-1), $K25) -> Rasayan
A26: 173162271836174 | B26: FALSE | E26: 2024-04-27 10:07:51 | F26: 2024-04-27 10:08:09 | G26: 21191609 | H26: cancelled | J26: 630473 | K26: Rasayan | L26: 652,13th cross,29th main road BTM 2nd stage,560078, Bangalore Karnataka | M26: Health Bar | N26: Bangalore | O26: 0 | P26: 646 | Q26: 646 | R26: 646 | S26: 580 | T26: 43 | U26: 0 | V26: 12.907799,77.613487 | W26: 1.9 | Y26: UPICollect | Z26: BTM 2nd Stage | AA26: FALSE | AB26: 0 | AC26: =DATEVALUE($E26) -> 45409 | AD26: BTM | AE26: =IFERROR( LEFT($K26, FIND(" -", K26)-1), $K26) -> Rasayan
A27: 173021459533483 | B27: TRUE | C27: TRYNEW | D27: [{"id":"f90d8119-321f-4158-a454-d7576a8e0a65","super_type":"SUPERTYPE_UNSPECIFIED","total_offer_discount":75,"discount_share":{"swiggy_discount":18.75,"store_discount":56.25,"alliance_discount":0},"discount_type":"PERCENTAGE","description":"30% off","fixed_charges":{"gp":{"id":"","final_price":0}}}] | E27: 2024-04-25 19:00:59 | F27: 2024-04-25 19:01:33 | G27: 21191609 | H27: Delivered | I27: [Record] | J27: 260968 | K27: Chowman | L27: SAI DURGA ENCLAVE, KATHA NO 1099, AND NO 833/1, GROUND FLOOR, BELLENDUR VILLAGE, VARTHUR HOBLI, BANGALORE, Mahadevapura , B.B.M.P East, Karnataka-560037 | M27: Sai Durga Enclave | N27: Bangalore | O27: 1950 | P27: 208 | Q27: 208 | R27: 208 | S27: 260 | T27: 40 | U27: 0 | V27: 12.92314229,77.6713331 | W27: 3.3 | X27: TRYNEW | Y27: UPICollect | Z27: Bellandur | AA27: TRUE | AB27: 0 | AC27: =DATEVALUE($E27) -> 45407 | AD27: Bellandur | AE27: =IFERROR( LEFT($K27, FIND(" -", K27)-1), $K27) -> Chowman
A28: 172937451496694 | B28: TRUE | C28: MISSEDYOU | D28: [{"id":"12337c67-3996-4380-afdd-b7cf7e3de7a3","super_type":"SUPERTYPE_UNSPECIFIED","total_offer_discount":100,"discount_share":{"swiggy_discount":48,"store_discount":52,"alliance_discount":0},"discount_type":"PERCENTAGE","description":"50% off","fixed_charges":{"gp":{"id":"","final_price":0}}}] | E28: 2024-04-24 19:40:51 | F28: 2024-04-24 19:41:11 | G28: 21191609 | H28: Delivered | I28: [Record] | J28: 742267 | K28: Paris Panini - Gourmet Sandwiches & Wraps | L28: Counter No. 23, 24 & 33, No. 53/2, Doddakannelli Village, Varthur Hobli, Bangalore, Mahadevapura , B.B.M.P East, Karnataka-560038 | M28: Sarjapur Road | N28: Bangalore | O28: 2384 | P28: 344 | Q28: 344 | R28: 344 | S28: 395 | T28: 61 | U28: 0 | V28: 12.90906249,77.68766132 | W28: 5.4 | X28: MISSEDYOU | Y28: UPICollect | Z28: Bellandur Sarjapur | AA28: TRUE | AB28: 0 | AC28: =DATEVALUE($E28) -> 45406 | AD28: Bellandur | AE28: =IFERROR( LEFT($K28, FIND(" -", K28)-1), $K28) -> Paris Panini
A29: 172865582370674 | B29: TRUE | C29: SWIGGYIT | D29: [{"id":"a95119de-61b8-489b-ad8b-1cf7a5d62a5e","super_type":"SUPERTYPE_UNSPECIFIED","total_offer_discount":50,"discount_share":{"swiggy_discount":15,"store_discount":35,"alliance_discount":0},"discount_type":"PERCENTAGE","description":"20% off","fixed_charges":{"gp":{"id":"","final_price":0}}}] | E29: 2024-04-23 23:43:02 | F29: 2024-04-23 23:43:23 | G29: 21191609 | H29: Delivered | I29: [Record] | J29: 29349 | K29: Frozen Bottle - Milkshakes, Desserts And Ice Cream | L29: 88, Celler Floor, 17th Cross, 14th main, Sector - 4, HSR, Bangalore | M29: HSR Layout | N29: Bangalore | O29: 1985 | P29: 301 | Q29: 301 | R29: 301 | S29: 289 | T29: 50 | U29: 0 | V29: 12.91233118,77.63839138 | W29: 1.7 | X29: SWIGGYIT | Y29: UPICollect | Z29: HSR Layout | AA29: TRUE | AB29: 0 | AC29: =DATEVALUE($E29) -> 45405 | AD29: HSR | AE29: =IFERROR( LEFT($K29, FIND(" -", K29)-1), $K29) -> Frozen Bottle
A30: 172849812190412 | B30: TRUE | C30: TRYNEW | D30: [{"id":"768dad50-eef1-40d7-bfd4-5327ee71bb5a","super_type":"SUPERTYPE_UNSPECIFIED","total_offer_discount":60,"discount_share":{"swiggy_discount":0,"store_discount":60,"alliance_discount":0},"discount_type":"PERCENTAGE","description":"30% off","fixed_charges":{"gp":{"id":"","final_price":0}}}] | E30: 2024-04-23 19:20:12 | F30: 2024-04-23 19:20:29 | G30: 21191609 | H30: Delivered | I30: [Record] | J30: 34366 | K30: Firangi Bake | L30: SHOP NO 2318,HSR LAYOUT SECTOR ONE,NEAR NIFT COLLEGE,BANGALORE | M30: Near NIFT College, Sector 1 | N30: Bangalore | O30: 1375 | P30: 310 | Q30: 310 | R30: 310 | S30: 325 | T30: 35 | U30: 0 | V30: 12.912101,77.65163400000006 | W30: 0.8 | X30: TRYNEW | Y30: UPICollect | Z30: HSR Layout | AA30: FALSE | AB30: 0 | AC30: =DATEVALUE($E30) -> 45405 | AD30: HSR | AE30: =IFERROR( LEFT($K30, FIND(" -", K30)-1), $K30) -> Firangi Bake
A31: 172765721740638 | B31: TRUE | C31: MDM150 | D31: [{"id":"24ecd13d-e27f-4858-9c2a-bdc2b708cce4","super_type":"SUPERTYPE_UNSPECIFIED","total_offer_discount":150,"discount_share":{"swiggy_discount":75,"store_discount":75,"alliance_discount":0},"discount_type":"FLAT","description":"Flat ₹150 off","fixed_charges":{"gp":{"id":"","final_price":0}}}] | E31: 2024-04-22 19:58:41 | F31: 2024-04-22 19:59:12 | G31: 21191609 | H31: Delivered | I31: [Record] | J31: 17036 | K31: Leon's - Burgers & Wings (Leon Grill) | L31: No.17, Ground Floor, 18th Cross Road, 3rd Sector, HSR Layout, Bangalore. | M31: HSR Layout | N31: Bangalore | O31: 1703 | P31: 724 | Q31: 724 | R31: 724 | S31: 797.57 | T31: 35 | U31: 0 | V31: 12.91181131,77.64374963 | W31: 1.6 | X31: MDM150 | Y31: UPICollect | Z31: HSR Layout | AA31: FALSE | AB31: 0 | AC31: =DATEVALUE($E31) -> 45404 | AD31: HSR | AE31: =IFERROR( LEFT($K31, FIND(" -", K31)-1), $K31) -> Leon's
A32: 172415621290914 | B32: TRUE | C32: MDM150 | D32: [{"id":"8cdbbc6c-7669-489e-b255-421d322ec80f","super_type":"SUPERTYPE_UNSPECIFIED","total_offer_discount":150,"discount_share":{"swiggy_discount":75,"store_discount":75,"alliance_discount":0},"discount_type":"FLAT","description":"Flat ₹150 off","fixed_charges":{"gp":{"id":"","final_price":0}}}] | E32: 2024-04-18 18:43:41 | F32: 2024-04-18 18:44:05 | G32: 21191609 | H32: Delivered | I32: [Record] | J32: 17036 | K32: Leon's - Burgers & Wings (Leon Grill) | L32: No.17, Ground Floor, 18th Cross Road, 3rd Sector, HSR Layout, Bangalore. | M32: HSR Layout | N32: Bangalore | O32: 1726 | P32: 252 | Q32: 252 | R32: 252 | S32: 349 | T32: 31 | U32: 0 | V32: 12.91181131,77.64374963 | W32: 0.9 | X32: MDM150 | Y32: UPICollect | Z32: HSR Layout | AA32: TRUE | AB32: 0 | AC32: =DATEVALUE($E32) -> 45400 | AD32: HSR | AE32: =IFERROR( LEFT($K32, FIND(" -", K32)-1), $K32) -> Leon's
A33: 171120236353593 | B33: TRUE | C33: MDM150 | D33: [{"id":"8cdbbc6c-7669-489e-b255-421d322ec80f","super_type":"SUPERTYPE_UNSPECIFIED","total_offer_discount":150,"discount_share":{"swiggy_discount":75,"store_discount":75,"alliance_discount":0},"discount_type":"FLAT","description":"Flat ₹150 off","fixed_charges":{"gp":{"id":"","final_price":0}}}] | E33: 2024-04-03 18:53:56 | F33: 2024-04-03 18:54:20 | G33: 21191609 | H33: Delivered | I33: [Record] | J33: 17036 | K33: Leon's - Burgers & Wings (Leon Grill) | L33: No.17, Ground Floor, 18th Cross Road, 3rd Sector, HSR Layout, Bangalore. | M33: HSR Layout | N33: Bangalore | O33: 836 | P33: 252 | Q33: 252 | R33: 252 | S33: 349 | T33: 29 | U33: 0 | V33: 12.91181131,77.64374963 | W33: 0.2 | X33: MDM150 | Y33: UPICollect | Z33: HSR Layout | AA33: TRUE | AB33: 0 | AC33: =DATEVALUE($E33) -> 45385 | AD33: HSR | AE33: =IFERROR( LEFT($K33, FIND(" -", K33)-1), $K33) -> Leon's
A34: 170949181342493 | B34: TRUE | C34: MDM150 | D34: [{"id":"8cdbbc6c-7669-489e-b255-421d322ec80f","super_type":"SUPERTYPE_UNSPECIFIED","total_offer_discount":150,"discount_share":{"swiggy_discount":75,"store_discount":75,"alliance_discount":0},"discount_type":"FLAT","description":"Flat ₹150 off","fixed_charges":{"gp":{"id":"","final_price":0}}}] | E34: 2024-04-01 19:23:01 | F34: 2024-04-01 19:23:06 | G34: 21191609 | H34: Delivered | I34: [Record] | J34: 17036 | K34: Leon's - Burgers & Wings (Leon Grill) | L34: No.17, Ground Floor, 18th Cross Road, 3rd Sector, HSR Layout, Bangalore. | M34: HSR Layout | N34: Bangalore | O34: 2224 | P34: 252 | Q34: 252 | R34: 252 | S34: 349 | T34: 34 | U34: 0 | V34: 12.91181131,77.64374963 | W34: 1.6 | X34: MDM150 | Y34: Cash | Z34: HSR Layout | AA34: FALSE | AB34: 0 | AC34: =DATEVALUE($E34) -> 45383 | AD34: HSR | AE34: =IFERROR( LEFT($K34, FIND(" -", K34)-1), $K34) -> Leon's
A35: 170849767634192 | B35: TRUE | C35: MDM150 | D35: [{"id":"8cdbbc6c-7669-489e-b255-421d322ec80f","super_type":"SUPERTYPE_UNSPECIFIED","total_offer_discount":150,"discount_share":{"swiggy_discount":75,"store_discount":75,"alliance_discount":0},"discount_type":"FLAT","description":"Flat ₹150 off","fixed_charges":{"gp":{"id":"","final_price":0}}}] | E35: 2024-03-31 15:46:07 | F35: 2024-03-31 15:46:25 | G35: 21191609 | H35: Delivered | I35: [Record] | J35: 17036 | K35: Leon's - Burgers & Wings (Leon Grill) | L35: No.17, Ground Floor, 18th Cross Road, 3rd Sector, HSR Layout, Bangalore. | M35: HSR Layout | N35: Bangalore | O35: 854 | P35: 252 | Q35: 252 | R35: 252 | S35: 349 | T35: 30 | U35: 0 | V35: 12.91181131,77.64374963 | W35: 1.6 | X35: MDM150 | Y35: UPICollect | Z35: HSR Layout | AA35: TRUE | AB35: 0 | AC35: =DATEVALUE($E35) -> 45382 | AD35: HSR | AE35: =IFERROR( LEFT($K35, FIND(" -", K35)-1), $K35) -> Leon's
A36: 170326417874188 | B36: TRUE | C36: SWIGGYIT | D36: [{"id":"16ef3f62-96d1-48fa-977b-3851da22b190","super_type":"SUPERTYPE_UNSPECIFIED","total_offer_discount":80,"discount_share":{"swiggy_discount":20,"store_discount":60,"alliance_discount":0},"discount_type":"PERCENTAGE","description":"40% off","fixed_charges":{"gp":{"id":"","final_price":0}}}] | E36: 2024-03-25 14:23:37 | F36: 2024-03-25 14:23:54 | G36: 21191609 | H36: Delivered | I36: [Record] | J36: 2675 | K36: Subway | L36: 36, 3rd Store, 7th Sector, 14th main, HSR Layout | M36: 7th Sector | N36: Bangalore | O36: 779 | P36: 252 | Q36: 252 | R36: 252 | S36: 300 | T36: 32 | U36: 0 | V36: 12.9118135,77.637958 | W36: 0.6 | X36: SWIGGYIT | Y36: UPICollect | Z36: Hsr Layout | AA36: TRUE | AB36: 0 | AC36: =DATEVALUE($E36) -> 45376 | AD36: HSR | AE36: =IFERROR( LEFT($K36, FIND(" -", K36)-1), $K36) -> Subway
A37: 169997934599848 | B37: TRUE | C37: FLATDEAL | D37: [{"id":"20f94987-8858-4c7d-bf7b-c2ff8a327fa8","super_type":"SUPERTYPE_UNSPECIFIED","total_offer_discount":99.99,"discount_share":{"swiggy_discount":0,"store_discount":99.99,"alliance_discount":0},"discount_type":"FLAT","description":"FLAT100 off","fixed_charges":{"gp":{"id":"","final_price":0}}}] | E37: 2024-03-21 19:08:54 | F37: 2024-03-21 19:09:08 | G37: 21191609 | H37: Delivered | I37: [Record] | J37: 2675 | K37: Subway | L37: 36, 3rd Store, 7th Sector, 14th main, HSR Layout | M37: 7th Sector | N37: Bangalore | O37: 2901 | P37: 596 | Q37: 596 | R37: 596 | S37: 649 | T37: 34 | U37: 0 | V37: 12.9118135,77.637958 | W37: 1.9 | X37: FLATDEAL | Y37: UPICollect | Z37: Hsr Layout | AA37: FALSE | AB37: 0 | AC37: =DATEVALUE($E37) -> 45372 | AD37: HSR | AE37: =IFERROR( LEFT($K37, FIND(" -", K37)-1), $K37) -> Subway
A38: 169054716176265 | B38: TRUE | C38: SWIGGYIT | D38: [{"id":"e7373c56-9ba3-49f4-be3d-f75ecf92675e","super_type":"SUPERTYPE_UNSPECIFIED","total_offer_discount":80,"discount_share":{"swiggy_discount":20,"store_discount":60,"alliance_discount":0},"discount_type":"PERCENTAGE","description":"40% off","fixed_charges":{"gp":{"id":"","final_price":0}}}] | E38: 2024-03-10 21:08:36 | F38: 2024-03-10 21:09:03 | G38: 21191609 | H38: Delivered | I38: [Record] | J38: 2675 | K38: Subway | L38: 36, 3rd Store, 7th Sector, 14th main, HSR Layout | M38: 7th Sector | N38: Bangalore | O38: 4130 | P38: 251 | Q38: 251 | R38: 251 | S38: 300 | T38: 57 | U38: 0 | V38: 12.9118135,77.637958 | W38: 1.9 | X38: SWIGGYIT | Y38: UPICollect | Z38: Hsr Layout | AA38: FALSE | AB38: 0 | AC38: =DATEVALUE($E38) -> 45361 | AD38: HSR | AE38: =IFERROR( LEFT($K38, FIND(" -", K38)-1), $K38) -> Subway
A39: 168959031219038 | B39: TRUE | C39: SWIGGYIT | D39: [{"id":"e7373c56-9ba3-49f4-be3d-f75ecf92675e","super_type":"SUPERTYPE_UNSPECIFIED","total_offer_discount":80,"discount_share":{"swiggy_discount":20,"store_discount":60,"alliance_discount":0},"discount_type":"PERCENTAGE","description":"40% off","fixed_charges":{"gp":{"id":"","final_price":0}}}] | E39: 2024-03-09 18:33:51 | F39: 2024-03-09 18:34:15 | G39: 21191609 | H39: Delivered | I39: [Record] | J39: 2675 | K39: Subway | L39: 36, 3rd Store, 7th Sector, 14th main, HSR Layout | M39: 7th Sector | N39: Bangalore | O39: 864 | P39: 302 | Q39: 302 | R39: 302 | S39: 349 | T39: 32 | U39: 0 | V39: 12.9118135,77.637958 | W39: 1.9 | X39: SWIGGYIT | Y39: UPICollect | Z39: Hsr Layout | AA39: TRUE | AB39: 0 | AC39: =DATEVALUE($E39) -> 45360 | AD39: HSR | AE39: =IFERROR( LEFT($K39, FIND(" -", K39)-1), $K39) -> Subway
A40: 168877172918547 | B40: FALSE | E40: 2024-03-08 19:49:32 | F40: 2024-03-08 19:49:59 | G40: 21191609 | H40: Delivered | I40: [Record] | J40: 464830 | K40: Bowl Soul | L40: No 526/A,Ganesh Complex,Ground floor,18th Main Road,HSR 3rd sector,Bangalore:560102 | M40: 3rd Sector | N40: Bangalore | O40: 2660 | P40: 154 | Q40: 154 | R40: 154 | S40: 249 | T40: 36 | U40: 0 | V40: 12.9054065,77.64410799999996 | W40: 1.8 | Y40: UPICollect | Z40: HSR Layout | AA40: FALSE | AB40: 0 | AC40: =DATEVALUE($E40) -> 45359 | AD40: HSR | AE40: =IFERROR( LEFT($K40, FIND(" -", K40)-1), $K40) -> Bowl Soul
...

Sheet Restaurant Area Correction
A1: restaurant_area_name | B1: area_name code
A2: BTM 2nd Stage | B2: BTM
A3: BTM 1st Stage | B3: BTM
A4: HSR Layout | B4: HSR
A5: Bellandur Sarjapur | B5: Bellandur
A6: ITI layout, Hosapalya | B6: Hosapalya
A7: Sarjapur Road | B7: Bellandur

Sheet Food Item Level Data
A1: order_id | B1: order_items.name | C1: order_items.is_veg | D1: order_items.quantity | E1: Veg/Non-Veg
A2: 175244332362622 | B2: Michel (Chicken & Mozza Sandwich) | C2: 0 | D2: 1 | E2: =IF(C2 = 0, "Non-Veg", "Veg") -> Non-Veg | G2: Consider 1: veg , 0: non-veg or vice-versa
A3: 175167017704058 | B3: Supreme Boneless Chicken Biryani | C3: 0 | D3: 1 | E3: =IF(C3 = 0, "Non-Veg", "Veg") -> Non-Veg
A4: 175167017704058 | B4: Mutton Bone Soup | C4: 0 | D4: 1 | E4: =IF(C4 = 0, "Non-Veg", "Veg") -> Non-Veg
A5: 175017114796029 | B5: Mississippi Mud Pie | C5: 0 | D5: 1 | E5: =IF(C5 = 0, "Non-Veg", "Veg") -> Non-Veg
A6: 175017114796029 | B6: Apple Crumble Pie | C6: 1 | D6: 1 | E6: =IF(C6 = 0, "Non-Veg", "Veg") -> Veg
A7: 174973046023416 | B7: Banana Peanutbutter Overnight Oats [350kcals][20gm protein] | C7: 1 | D7: 1 | E7: =IF(C7 = 0, "Non-Veg", "Veg") -> Veg
A8: 174973046023416 | B8: Dark Chocolate Smoothie Bowl. | C8: 1 | D8: 1 | E8: =IF(C8 = 0, "Non-Veg", "Veg") -> Veg
A9: 174906705849277 | B9: Chicken Kheema Lasagne | C9: 0 | D9: 1 | E9: =IF(C9 = 0, "Non-Veg", "Veg") -> Non-Veg
A10: 174906705849277 | B10: Corn & Pepper Lasagne | C10: 1 | D10: 1 | E10: =IF(C10 = 0, "Non-Veg", "Veg") -> Veg
A11: 174329455765789 | B11: Veg. Ramyun | C11: 1 | D11: 1 | E11: =IF(C11 = 0, "Non-Veg", "Veg") -> Veg
A12: 174329455765789 | B12: Chicken Katsu Ramyun | C12: 0 | D12: 1 | E12: =IF(C12 = 0, "Non-Veg", "Veg") -> Non-Veg
A13: 174318296922309 | B13: Onion Rings | C13: 1 | D13: 1 | E13: =IF(C13 = 0, "Non-Veg", "Veg") -> Veg
A14: 174318296922309 | B14: Cajun Spiced Fries | C14: 1 | D14: 1 | E14: =IF(C14 = 0, "Non-Veg", "Veg") -> Veg
... A171: 171863054117 | B171: Open Butter Masala Dosa | C171: 1 | D171: 1 | E171: =IF(C171 = 0, "Non-Veg", "Veg") -> Veg

Sheet Restaurant Level Analysis
A1: Restaurant Names | B1: Total Orders | C1: Ranks
A2: {=_xlfn.UNIQUE(Swiggy_Orders_Data!$K$2:$K$108)} -> Paris Panini - Gourmet Sandwiches & Wraps | B2: =COUNTIF(Swiggy_Orders_Data!$K$2:$K$108, $A2) -> 6 | C2: =_xlfn.RANK.EQ(B2, $B$2:$B$44, 0) -> 4 | E2: How many orders are placed from the different restaurants so far? Also show it as a visual | P2: {=_xlfn.XLOOKUP(1, $C$2:$C$44,_xlfn.ANCHORARRAY( $A$2))} -> Subway
A3: Nandhana Palace | B3: =COUNTIF(Swiggy_Orders_Data!$K$2:$K$108, $A3) -> 2 | C3: =_xlfn.RANK.EQ(B3, $B$2:$B$44, 0) -> 13 | E3: From which restaurant most orders have been placed?
A4: The Ganache Factory - Cakes & Desserts | B4: =COUNTIF(Swiggy_Orders_Data!$K$2:$K$108, $A4) -> 6 | C4: =_xlfn.RANK.EQ(B4, $B$2:$B$44, 0) -> 4
A5: Rasayan | B5: =COUNTIF(Swiggy_Orders_Data!$K$2:$K$108, $A5) -> 8 | C5: =_xlfn.RANK.EQ(B5, $B$2:$B$44, 0) -> 2
A6: Firangi Bake | B6: =COUNTIF(Swiggy_Orders_Data!$K$2:$K$108, $A6) -> 4 | C6: =_xlfn.RANK.EQ(B6, $B$2:$B$44, 0) -> 8
A7: Daily Sushi | B7: =COUNTIF(Swiggy_Orders_Data!$K$2:$K$108, $A7) -> 6 | C7: =_xlfn.RANK.EQ(B7, $B$2:$B$44, 0) -> 4
A8: Naalnaad Mane | B8: =COUNTIF(Swiggy_Orders_Data!$K$2:$K$108, $A8) -> 3 | C8: =_xlfn.RANK.EQ(B8, $B$2:$B$44, 0) -> 11
A9: Theobroma | B9: =COUNTIF(Swiggy_Orders_Data!$K$2:$K$108, $A9) -> 2 | C9: =_xlfn.RANK.EQ(B9, $B$2:$B$44, 0) -> 13
A10: Love And Crumble | B10: =COUNTIF(Swiggy_Orders_Data!$K$2:$K$108, $A10) -> 1 | C10: =_xlfn.RANK.EQ(B10, $B$2:$B$44, 0) -> 21
A11: Homely | B11: =COUNTIF(Swiggy_Orders_Data!$K$2:$K$108, $A11) -> 1 | C11: =_xlfn.RANK.EQ(B11, $B$2:$B$44, 0) -> 21
A12: Chowman | B12: =COUNTIF(Swiggy_Orders_Data!$K$2:$K$108, $A12) -> 1 | C12: =_xlfn.RANK.EQ(B12, $B$2:$B$44, 0) -> 21
A13: Frozen Bottle - Milkshakes, Desserts And Ice Cream | B13: =COUNTIF(Swiggy_Orders_Data!$K$2:$K$108, $A13) -> 1 | C13: =_xlfn.RANK.EQ(B13, $B$2:$B$44, 0) -> 21
A14: Leon's - Burgers & Wings (Leon Grill) | B14: =COUNTIF(Swiggy_Orders_Data!$K$2:$K$108, $A14) -> 8 | C14: =_xlfn.RANK.EQ(B14, $B$2:$B$44, 0) -> 2
A15: Subway | B15: =COUNTIF(Swiggy_Orders_Data!$K$2:$K$108, $A15) -> 11 | C15: =_xlfn.RANK.EQ(B15, $B$2:$B$44, 0) -> 1
... A44: Table for Tous | B44: =COUNTIF(Swiggy_Orders_Data!$K$2:$K$108, $A44) -> 1 | C44: =_xlfn.RANK.EQ(B44, $B$2:$B$44, 0) -> 21

Sheet Area Level Analysis
A2: Number of orders from different area codes.
B3: Area Codes | C3: Total Orders
B4: Arekere | C4: 4
B5: Bellandur | C5: 11
B6: Bommanahalli | C6: 4
B7: BTM | C7: 10
B8: Devarabeesanahalli | C8: 4
B9: Hosapalya | C9: 3
B10: HSR | C10: 44
B11: Indiranagar | C11: 1
B12: Jayanagar | C12: 4
B13: JP Nagar | C13: 6
B14: Koramangala | C14: 14
B15: Malleshwaram | C15: 1
... B17: Grand Total | C17: 107
A20: Food item which is ordered the most from each area.
B21: Area Codes | C21: Food item | D21: Total Orders
B22: Arekere | C22: Koli Curry With Ney Kulu/Noolputtu | D22: 2
B23: Bellandur | C23: Ghee Gulab Jamun (2 Pcs) | D23: 2
B24: Bommanahalli | C24: Idiyappam | D24: 3
B25: BTM | C25: Dark Chocolate Smoothie Bowl. | D25: 5
B26: Devarabeesanahalli | C26: Blueberry Cheese Cake | D26: 2
B27: Hosapalya | C27: Paris Delice (Buff) | D27: 2
B28: HSR | C28: Single Lamb Cheese Burger | D28: 6
B29: Indiranagar | C29: Trapper Creek | D29: 1
B30: Jayanagar | C30: Apple Crumble Pie | D30: 1
B31: JP Nagar | C31: Michel (Chicken & Mozza Sandwich) | D31: 3
B32: Koramangala | C32: Melted Cheese Chicken Shawarma | D32: 5
B33: Malleshwaram | C33: Dark Chocolate Chunk Sea Salt | D33: 1
B34: Yelahanka | C34: Ferrero Magic | D34: 1
B35: Grand Total | D35: 34

Sheet Monthly Expenditure
A2: Monthly spending behaviour:
B6: Months | C6: Sum of order_total
B7: Daily Sushi | C7: 3337
B8: Plan B | C8: 3274
B9: Rasayan | C9: 3351
B10: Subway | C10: 3463
B11: The Ganache Factory - Cakes & Desserts | C11: 3645
B12: Grand Total | C12: 17070

Sheet Food Items Analysis
A2: Q1: Total Food items : | B2: =COUNTA(_xlfn.UNIQUE('Food Item Level Data'!$B$2:$B$171)) -> 110
A3: Q2: Count of each food item ordered: | B3: Food items | C3: Total Orders
B4: Single Lamb Cheese Burger | C4: 6
B5: Grand Total | C5: 6

Sheet KPIs
A2: 1. Which is the most ordered type of food? Veg or Non-Veg?
A3: Type of Food | B3: Total Orders
A4: Non-Veg | B4: 102
A5: Veg | B5: 68
A6: Grand Total | B6: 170
A9: 2. How many times the Food was delivered on time & delayed?
A10: On time Delivery? | B10: Total Orders
A11: FALSE | B11: 0.56074766
A12: TRUE | B12: 0.43925234
A13: Grand Total | B13: 1
A16: Q3: Canceled Orders: | C16: =COUNTIF(Swiggy_Orders_Data!$H$1:$H$108, "cancelled")/ COUNTA(Swiggy_Orders_Data!$A$2:$A$108) -> 0.028037383
A17: Q4: Toal Orders: | C17: =COUNTA(Swiggy_Orders_Data!$A$2:$A$108) -> 107
A18: Q5: Total Revenue : | C18: =SUMIFS(Swiggy_Orders_Data!$R$2:$R$108, Swiggy_Orders_Data!$H$2:$H$108, "Delivered") -> 42064
A19: Q6: Average Order Amount: | C19: =AVERAGE(Swiggy_Orders_Data!$R$2:$R$108) -> 410.8785
A20: Q7: Most Prefered restaurant: | C20: ='Restaurant Level Analysis'!P2 -> Subway
A21: Q8: Most re-ordered item: | C21: ='Food Items Analysis'!$B$4 -> Single Lamb Cheese Burger

Sheet Dashboard
A1: Swiggy Order Analysis
A3: KPI
A5: =KPIs!$C$18 -> 42064 | B5: =KPIs!$C$17 -> 107 | C5: =KPIs!$C$19 -> 410.8785 | F5: =KPIs!C20 -> Subway | I5: =KPIs!$C$21 -> Single Lamb Cheese Burger
A9: MOM Expense( monthly number of orders & revenue)
A32: Area wise Order Count
A54: Composition of Veg and Non-Veg items
A72: Delivery Metrics
A74: =AVERAGE(Swiggy_Orders_Data!$O$2:$O$108) / 60 -> 33.457321 | B74: =AVERAGE(Swiggy_Orders_Data!$W$2:$W$108) -> 2.9934579
A78: % of orders delivered on time
A94: Orders Trend
A114: Top Restaurants By Revenue

Sheet Insights
A1: Key Insights:
A3: 1. Order volume shows clear peak periods, indicating higher demand during specific days and time slots.
A5: 2. A few cities contribute a significant share of total revenue, highlighting high-performing markets.
A7: 3. Top 5 restaurants account for a large portion of revenue, indicating revenue concentration among key partners.
A9: 4. Evening and dinner time slots generate the highest number of orders, reflecting customer ordering behavior.
A11: 5. Order trends indicate consistent demand with occasional spikes during peak periods.

Sheet SQL_Monthly_Orders
A1: Monthly Orders Count
B4: month | C4: total_orders
B5: 2023-07 | C5: 3
B6: 2023-08 | C6: 9
B7: 2023-09 | C7: 11
B8: 2023-10 | C8: 8
B9: 2023-11 | C9: 8
B10: 2023-12 | C10: 6
B11: 2024-01 | C11: 8
B12: 2024-02 | C12: 11
B13: 2024-03 | C13: 10
B14: 2024-04 | C14: 10
B15: 2024-05 | C15: 23

Sheet SQL_Monthly_Revenue
A1: Monthly Revenue
B4: month | C4: total_revenue
B5: 2023-07 | C5: 1492
B6: 2023-08 | C6: 3548
B7: 2023-09 | C7: 6319
B8: 2023-10 | C8: 1958
B9: 2023-11 | C9: 2402
B10: 2023-12 | C10: 2678
B11: 2024-01 | C11: 4160
B12: 2024-02 | C12: 3580
B13: 2024-03 | C13: 3680
B14: 2024-04 | C14: 3778
B15: 2024-05 | C15: 10369

Sheet SQL_Top_Restaurants
A1: Top 5 Restaurants by Revenue
B4: restaurant_name | C4: total_revenue
B5: The Ganache Factory - Cakes & Desserts | C5: 3645
B6: Subway | C6: 3463
B7: Rasayan | C7: 3351
B8: Daily Sushi | C8: 3337
B9: Plan B | C9: 3274
